Workbook

Sheet Assumptions
A1: GAMMA COMMUNICATIONS PLC | FP&A 3-STATEMENT MODEL
A2: Assumptions & Drivers | All figures in £m unless stated
A4: Driver | B4: FY2022A | C4: FY2023A | D4: FY2024A | E4: FY2025A | F4: FY2026E | G4: FY2027E
A5: REVENUE DRIVERS
A6: Gamma Business revenue (£m) | B6: 309.4 | C6: 332.2 | D6: 368.9 | E6: 374.6 | F6: =E6*(1+F7) -> 382.092 | G6: =F6*(1+G7) -> 389.73384
A7: YoY growth % | C7: =(C6-B6)/B6 -> 0.073691015 | D7: =(D6-C6)/C6 -> 0.11047562 | E7: =(E6-D6)/D6 -> 0.015451342 | F7: =$B$47 -> 0.02 | G7: =$B$47 -> 0.02
A8: Gamma Enterprise revenue (£m) | B8: 102 | C8: 110.1 | D8: 126.5 | E8: 130.5 | F8: =E8*(1+F9) -> 135.72 | G8: =F8*(1+G9) -> 141.1488
A9: YoY growth % | C9: =(C8-B8)/B8 -> 0.079411765 | D9: =(D8-C8)/C8 -> 0.1489555 | E9: =(E8-D8)/D8 -> 0.031620553 | F9: =$B$48 -> 0.04 | G9: =$B$48 -> 0.04
A10: Gamma Germany revenue (£m) | B10: 43 | C10: 47.2 | D10: 54.3 | E10: 110.2 | F10: =E10*(1+F11) -> 126.73 | G10: =F10*(1+G11) -> 145.7395
A11: YoY growth % | C11: =(C10-B10)/B10 -> 0.097674419 | D11: =(D10-C10)/C10 -> 0.15042373 | E11: =(E10-D10)/D10 -> 1.0294659 | F11: =$B$49 -> 0.15 | G11: =$B$49 -> 0.15
A12: Other Europe revenue (£m) | B12: 30.2 | C12: 32.2 | D12: 29.7 | E12: 30.5 | F12: =E12*(1+F13) -> 31.415 | G12: =F12*(1+G13) -> 32.35745
A13: YoY growth % | B13: 18400 | C13: =(C12-B12)/B12 -> 0.066225166 | D13: =(D12-C12)/C12 -> -0.077639752 | E13: =(E12-D12)/D12 -> 0.026936027 | F13: =$B$50 -> 0.03 | G13: =$B$50 -> 0.03
A14: Total Revenue (£m) | B14: =B6+B8+B10+B12 -> 484.6 | C14: =C6+C8+C10+C12 -> 521.7 | D14: =D6+D8+D10+D12 -> 579.4 | E14: =E6+E8+E10+E12 -> 645.8 | F14: =F6+F8+F10+F12 -> 675.957 | G14: =G6+G8+G10+G12 -> 708.97959
E15: 0.1 | F15: 0.08 | G15: 0.07
A16: COST & MARGIN ASSUMPTIONS
A17: COGS as % of revenue | B17: 0.489 | C17: 0.488 | D17: 0.482 | E17: 0.461 | F17: =$B$51 -> 0.455 | G17: =$B$51 -> 0.455
A18: Operating cost growth YoY | C18: 0.04 | D18: 0.04 | E18: 0.05 | F18: =$B$52 -> 0.03 | G18: =$B$52 -> 0.03
A19: D&A as % of revenue | B19: 0.056 | C19: 0.06 | D19: 0.058 | E19: 0.062 | F19: =$B$53 -> 0.08 | G19: =$B$53 -> 0.08
A20: Interest rate on debt (%) | B20: 0.02 | C20: 0.015 | D20: 0.01 | E20: 0.055 | F20: 0.055 | G20: 0.055
A21: Tax rate (%) | B21: 0.237 | C21: 0.249 | D21: 0.27 | E21: 0.259 | F21: =$B$54 -> 0.25 | G21: =$B$54 -> 0.25
A23: BALANCE SHEET ASSUMPTIONS
A24: Capex as % of revenue | B24: 0.042 | C24: 0.044 | D24: 0.033 | E24: 0.037 | F24: 0.037 | G24: 0.035
A25: DSO – Days Sales Outstanding | B25: 56 | C25: 53 | D25: 50 | E25: 44 | F25: 43 | G25: 42
A26: DPO – Days Payable Outstanding | B26: 83 | C26: 95 | D26: 89 | E26: 88 | F26: 88 | G26: 88
A27: Inventory days | B27: 16 | C27: 17 | D27: 13 | E27: 10 | F27: 9 | G27: 8
A30: SCENARIO ANALYSIS — Change cell B32 to switch between cases
A31: Select Bear / Base / Bull in the dropdown below. All FY2026E and FY2027E assumptions update automatically.
A32: ▶ Active Scenario | B32: Base | C32: ← click to change
A33: =IF($B$32="Bear","⚠ BEAR CASE — stressed assumptions in forecast columns",IF($B$32="Bull","✓ BULL CASE — optimistic assumptions in forecast columns","● BASE CASE — central assumptions in forecast columns")) -> ● BASE CASE — central assumptions in forecast columns
A35: SCENARIO ASSUMPTIONS (edit these values)
A36: Assumption | B36: Bear 🔴 | C36: Base ⚫ | D36: Bull 🟢
A37: Gamma Business growth % | B37: 0 | C37: 0.02 | D37: 0.04
A38: Gamma Enterprise growth % | B38: 0.02 | C38: 0.04 | D38: 0.06
A39: Gamma Germany growth % | B39: 0.05 | C39: 0.15 | D39: 0.25
A40: Other Europe growth % | B40: 0.01 | C40: 0.03 | D40: 0.05
A41: COGS % of revenue | B41: 0.47 | C41: 0.455 | D41: 0.44
A42: Opex growth % | B42: 0.05 | C42: 0.03 | D42: 0.02
A43: D&A % of revenue | B43: 0.09 | C43: 0.08 | D43: 0.07
A44: Tax rate % | B44: 0.26 | C44: 0.25 | D44: 0.24
A46: ACTIVE VALUES (formula-driven — feeds into forecast columns)
...

Sheet P&L
A1: GAMMA COMMUNICATIONS PLC | INCOME STATEMENT (£m)
A2: All figures £m | Blue = actual inputs | Black = formula | Green = cross-sheet | Source: Annual Reports 2022-2025
F3: ◀ FORECAST ▶
A4: £m | B4: FY2022A | C4: FY2023A | D4: FY2024A | E4: FY2025A | F4: FY2026E | G4: FY2027E
A5: REVENUE BY SEGMENT
A6: Gamma Business | B6: =Assumptions!B6 -> 309.4 | C6: =Assumptions!C6 -> 332.2 | D6: =Assumptions!D6 -> 368.9 | E6: =Assumptions!E6 -> 374.6 | F6: =Assumptions!F6 -> 382.092 | G6: =Assumptions!G6 -> 389.73384
A7: Gamma Enterprise | B7: =Assumptions!B8 -> 102 | C7: =Assumptions!C8 -> 110.1 | D7: =Assumptions!D8 -> 126.5 | E7: =Assumptions!E8 -> 130.5 | F7: =Assumptions!F8 -> 135.72 | G7: =Assumptions!G8 -> 141.1488
A8: Gamma Germany | B8: =Assumptions!B10 -> 43 | C8: =Assumptions!C10 -> 47.2 | D8: =Assumptions!D10 -> 54.3 | E8: =Assumptions!E10 -> 110.2 | F8: =Assumptions!F10 -> 126.73 | G8: =Assumptions!G10 -> 145.7395
A9: Other Europe | B9: =Assumptions!B12 -> 30.2 | C9: =Assumptions!C12 -> 32.2 | D9: =Assumptions!D12 -> 29.7 | E9: =Assumptions!E12 -> 30.5 | F9: =Assumptions!F12 -> 31.415 | G9: =Assumptions!G12 -> 32.35745
A10: Total Revenue | B10: =B6+B7+B8+B9 -> 484.6 | C10: =C6+C7+C8+C9 -> 521.7 | D10: =D6+D7+D8+D9 -> 579.4 | E10: =E6+E7+E8+E9 -> 645.8 | F10: =F6+F7+F8+F9 -> 675.957 | G10: =G6+G7+G8+G9 -> 708.97959
A12: COST OF SALES & GROSS PROFIT
A13: Cost of sales | B13: -236.9 | C13: -254.5 | D13: -279.1 | E13: -297.6 | F13: =-F10*Assumptions!F17 -> -307.56043 | G13: =-G10*Assumptions!G17 -> -322.58571
A14: Gross Profit | B14: =B10+B13 -> 247.7 | C14: =C10+C13 -> 267.2 | D14: =D10+D13 -> 300.3 | E14: =E10+E13 -> 348.2 | F14: =F10+F13 -> 368.39657 | G14: =G10+G13 -> 386.39388
A15: Gross margin % | B15: =B14/B10 -> 0.51114321 | C15: =C14/C10 -> 0.51217175 | D15: =D14/D10 -> 0.51829479 | E15: =E14/E10 -> 0.53917622 | F15: =F14/F10 -> 0.545 | G15: =G14/G10 -> 0.545
A17: OPERATING COSTS (below gross profit, above Adjusted EBITDA)
A18: Employee & related costs | B18: -64.2 | C18: -68.8 | D18: -78.7 | E18: -92.9 | F18: =E18*(1+Assumptions!F18) -> -95.687 | G18: =F18*(1+Assumptions!G18) -> -98.55761
A19: Technology & network opex | B19: -42.8 | C19: -45.9 | D19: -52.4 | E19: -61.9 | F19: =E19*(1+Assumptions!F18) -> -63.757 | G19: =F19*(1+Assumptions!G18) -> -65.66971
A20: Sales, marketing & admin | B20: -35.6 | C20: -38.2 | D20: -43.7 | E20: -51.6 | F20: =E20*(1+Assumptions!F18) -> -53.148 | G20: =F20*(1+Assumptions!G18) -> -54.74244
A21: Total Operating Costs | B21: =SUM(B18:B20) -> -142.6 | C21: =SUM(C18:C20) -> -152.9 | D21: =SUM(D18:D20) -> -174.8 | E21: =SUM(E18:E20) -> -206.4 | F21: =SUM(F18:F20) -> -212.592 | G21: =SUM(G18:G20) -> -218.96976
A23: ADJUSTED EBITDA — Primary management metric
A24: Adjusted EBITDA | B24: 105.1 | C24: 114.3 | D24: 125.5 | E24: 141.7 | F24: =F14+F21 -> 155.80456 | G24: =G14+G21 -> 167.42412
A25: Adjusted EBITDA margin % | B25: =B24/B10 -> 0.2168799 | C25: =C24/C10 -> 0.21909143 | D25: =D24/D10 -> 0.21660338 | E25: =E24/E10 -> 0.21941778 | F25: =F24/F10 -> 0.23049479 | G25: =G24/G10 -> 0.23614801
A27: D&A, EXCEPTIONAL ITEMS & EBIT
A28: Depreciation & amortisation | B28: -27.2 | C28: -31.3 | D28: -33.8 | E28: -40 | F28: =-F10*Assumptions!F19 -> -54.07656 | G28: =-G10*Assumptions!G19 -> -56.718367
A29: Exceptional items | B29: -12.5 | C29: -16 | D29: 0 | E29: -10.6 | F29: 0 | G29: 0
A30: EBIT (Operating Profit) | B30: =B24+B28+B29 -> 65.4 | C30: =C24+C28+C29 -> 67 | D30: =D24+D28+D29 -> 91.7 | E30: =E24+E28+E29 -> 91.1 | F30: =F24+F28+F29 -> 101.728 | G30: =G24+G28+G29 -> 110.70575
A31: EBIT margin % | B31: =B30/B10 -> 0.13495667 | C31: =C30/C10 -> 0.1284263 | D31: =D30/D10 -> 0.15826717 | E31: =E30/E10 -> 0.14106535 | F31: =F30/F10 -> 0.15049479 | G31: =G30/G10 -> 0.15614801
A33: BELOW THE LINE & NET INCOME
A34: Finance income | B34: 0.8 | C34: 5.4 | D34: 7.1 | E34: 2.9 | F34: 1.5 | G34: 2
A35: Finance expense | B35: -1.3 | C35: -0.9 | D35: -1.8 | E35: -6.1 | F35: -6.5 | G35: -6
A36: Profit Before Tax | B36: =B30+B34+B35 -> 64.9 | C36: =C30+C34+C35 -> 71.5 | D36: =D30+D34+D35 -> 97 | E36: =E30+E34+E35 -> 87.9 | F36: =F30+F34+F35 -> 96.728005 | G36: =G30+G34+G35 -> 106.70575
A37: Income tax | B37: -15.4 | C37: -17.8 | D37: -25.8 | E37: -22.7 | F37: =-MAX(F36,0)*Assumptions!F21 -> -24.182001 | G37: =-MAX(G36,0)*Assumptions!G21 -> -26.676437
A38: Net Income | B38: =B36+B37 -> 49.5 | C38: =C36+C37 -> 53.7 | D38: =D36+D37 -> 71.2 | E38: =E36+E37 -> 65.2 | F38: =F36+F37 -> 72.546004 | G38: =G36+G37 -> 80.029312
A39: Net margin % | B39: =B38/B10 -> 0.1021461 | C39: =C38/C10 -> 0.10293272 | D39: =D38/D10 -> 0.12288574 | E39: =E38/E10 -> 0.10096005 | F39: =F38/F10 -> 0.1073234 | G39: =G38/G10 -> 0.11287957

Sheet BalanceSheet
A1: GAMMA COMMUNICATIONS PLC | BALANCE SHEET (£m)
A2: All figures £m | Blue = input | Black = formula | Green = cross-sheet link
A4: £m | B4: FY2022A | C4: FY2023A | D4: FY2024A | E4: FY2025A | F4: FY2026E | G4: FY2027E
A5: NON-CURRENT ASSETS
A6: PP&E (net book value) | B6: 33.8 | C6: 30.5 | D6: 33.6 | E6: 40 | F6: =E6+'P&L'!F10*Assumptions!F24+'P&L'!F28 -> 10.933849 | G6: =F6+'P&L'!G10*Assumptions!G24+'P&L'!G28 -> -20.970233
A7: Intangible assets | B7: 124.3 | C7: 154.7 | D7: 189.3 | E7: 396.8 | F7: =E7*0.97 -> 384.896 | G7: =F7*0.97 -> 373.34912
A8: Total Non-Current Assets | B8: =B6+B7 -> 158.1 | C8: =C6+C7 -> 185.2 | D8: =D6+D7 -> 222.9 | E8: =E6+E7 -> 436.8 | F8: =F6+F7 -> 395.82985 | G8: =G6+G7 -> 352.37889
A10: CURRENT ASSETS
A11: Trade receivables | B11: 75 | C11: 76.1 | D11: 80.4 | E11: 78.4 | F11: ='P&L'!F10/365*Assumptions!F25 -> 79.63329 | G11: ='P&L'!G10/365*Assumptions!G25 -> 81.581213
A12: Inventory | B12: 10.2 | C12: 11.8 | D12: 10 | E12: 7.5 | F12: =-'P&L'!F13/365*Assumptions!F27 -> 7.583682 | G12: =-'P&L'!G13/365*Assumptions!G27 -> 7.0703718
A13: Prepayments & other | B13: 34.4 | C13: 32.5 | D13: 35 | E13: 41.8 | F13: ='P&L'!F10*0.025 -> 16.898925 | G13: ='P&L'!G10*0.025 -> 17.72449
A14: Cash & cash equivalents | B14: 94.6 | C14: 136.5 | D14: 153.7 | E14: 23.7 | F14: 60 | G14: 95
A15: Total Current Assets | B15: =SUM(B11:B14) -> 214.2 | C15: =SUM(C11:C14) -> 256.9 | D15: =SUM(D11:D14) -> 279.1 | E15: =SUM(E11:E14) -> 151.4 | F15: =SUM(F11:F14) -> 164.1159 | G15: =SUM(G11:G14) -> 201.37607
A17: TOTAL ASSETS | B17: =B8+B15 -> 372.3 | C17: =C8+C15 -> 442.1 | D17: =D8+D15 -> 502 | E17: =E8+E15 -> 588.2 | F17: =F8+F15 -> 559.94575 | G17: =G8+G15 -> 553.75496
A19: CURRENT LIABILITIES
A20: Trade payables | B20: -54 | C20: -66.5 | D20: -68.4 | E20: -70.3 | F20: -72 | G20: -74
A21: Accruals & deferred income | B21: -18.6 | C21: -22.6 | D21: -26.6 | E21: -40 | F21: =E21*1.03 -> -41.2 | G21: =F21*1.03 -> -42.436
A22: Current portion of debt | B22: -0.4 | C22: -0.3 | D22: -2 | E22: -5.2 | F22: =E22 -> -5.2 | G22: =F22 -> -5.2
A23: Total Current Liabilities | B23: =SUM(B20:B22) -> -73 | C23: =SUM(C20:C22) -> -89.4 | D23: =SUM(D20:D22) -> -97 | E23: =SUM(E20:E22) -> -115.5 | F23: =SUM(F20:F22) -> -118.4 | G23: =SUM(G20:G22) -> -121.636
A25: NON-CURRENT LIABILITIES
A26: Long-term borrowings | B26: -1.7 | C26: -1.4 | D26: -5.9 | E26: -45.6 | F26: -40.6 | G26: -35.6
A27: Deferred tax liability | B27: -11.3 | C27: -10.4 | D27: -17.6 | E27: -48.8 | F27: -50 | G27: -52
A28: Total Non-Current Liabilities | B28: =B26+B27 -> -13 | C28: =C26+C27 -> -11.8 | D28: =D26+D27 -> -23.5 | E28: =E26+E27 -> -94.4 | F28: =F26+F27 -> -90.6 | G28: =G26+G27 -> -87.6
A29: Total debt (current + LT) – used for interest | B29: =ABS(B22)+ABS(B26) -> 2.1 | C29: =ABS(C22)+ABS(C26) -> 1.7 | D29: =ABS(D22)+ABS(D26) -> 7.9 | E29: =ABS(E22)+ABS(E26) -> 50.8 | F29: =ABS(F22)+ABS(F26) -> 45.8 | G29: =ABS(G22)+ABS(G26) -> 40.8
A31: EQUITY
A32: Share capital & share premium | B32: 18.2 | C32: 22.9 | D32: 23.5 | E32: 23.5 | F32: =E32 -> 23.5 | G32: =F32 -> 23.5
A33: Retained earnings | B33: =B17+B23+B28-B32 -> 268.1 | C33: =C17+C23+C28-C32 -> 318 | D33: =D17+D23+D28-D32 -> 358 | E33: =E17+E23+E28-E32 -> 354.8 | F33: =F17+F23+F28-F32 -> 327.44575 | G33: =G17+G23+G28-G32 -> 321.01896
A34: Total Equity | B34: =B32+B33 -> 286.3 | C34: =C32+C33 -> 340.9 | D34: =D32+D33 -> 381.5 | E34: =E32+E33 -> 378.3 | F34: =F32+F33 -> 350.94575 | G34: =G32+G33 -> 344.51896
A36: TOTAL LIABILITIES & EQUITY | B36: =B34-B23-B28 -> 372.3 | C36: =C34-C23-C28 -> 442.1 | D36: =D34-D23-D28 -> 502 | E36: =E34-E23-E28 -> 588.2 | F36: =F34-F23-F28 -> 559.94575 | G36: =G34-G23-G28 -> 553.75496
A37: Balance check (Assets = L+E) | B37: =IF(ABS(B17-B36)<1,"✓ Balanced","✗ ERROR") -> ✓ Balanced | C37: =IF(ABS(C17-C36)<1,"✓ Balanced","✗ ERROR") -> ✓ Balanced | D37: =IF(ABS(D17-D36)<1,"✓ Balanced","✗ ERROR") -> ✓ Balanced | E37: =IF(ABS(E17-E36)<1,"✓ Balanced","✗ ERROR") -> ✓ Balanced | F37: =IF(ABS(F17-F36)<1,"✓ Balanced","✗ ERROR") -> ✓ Balanced | G37: =IF(ABS(G17-G36)<1,"✓ Balanced","✗ ERROR") -> ✓ Balanced

Sheet CashFlow
A1: GAMMA COMMUNICATIONS PLC | CASH FLOW STATEMENT (£m)
A2: All figures £m | Indirect method
A4: £m | B4: FY2022A | C4: FY2023A | D4: FY2024A | E4: FY2025A | F4: FY2026E | G4: FY2027E
A5: OPERATING ACTIVITIES
A6: Net income | B6: ='P&L'!B36 -> 64.9 | C6: ='P&L'!C36 -> 71.5 | D6: ='P&L'!D36 -> 97 | E6: ='P&L'!E36 -> 87.9 | F6: ='P&L'!F36 -> 96.728005 | G6: ='P&L'!G36 -> 106.70575
A7: Add back: D&A | B7: =-'P&L'!B28 -> 27.2 | C7: =-'P&L'!C28 -> 31.3 | D7: =-'P&L'!D28 -> 33.8 | E7: =-'P&L'!E28 -> 40 | F7: =-'P&L'!F28 -> 54.07656 | G7: =-'P&L'!G28 -> 56.718367
A8: Decrease / (increase) in trade receivables | B8: 0 | C8: -1.1 | D8: -4.3 | E8: 2 | F8: =BalanceSheet!E11-BalanceSheet!F11 -> -1.2332904 | G8: =BalanceSheet!F11-BalanceSheet!G11 -> -1.9479227
A9: Decrease / (increase) in inventory | B9: 0 | C9: -1.6 | D9: 1.8 | E9: 2.5 | F9: =BalanceSheet!E12-BalanceSheet!F12 -> -0.083681959 | G9: =BalanceSheet!F12-BalanceSheet!G12 -> 0.51331016
A10: Increase / (decrease) in trade payables | B10: 0 | C10: -12.5 | D10: -1.9 | E10: -1.9 | F10: =BalanceSheet!F20-BalanceSheet!E20 -> -1.7 | G10: =BalanceSheet!G20-BalanceSheet!F20 -> -2
A11: Increase / (decrease) in accruals | B11: 0 | C11: -4 | D11: -4 | E11: -13.4 | F11: =BalanceSheet!F21-BalanceSheet!E21 -> -1.2 | G11: =BalanceSheet!G21-BalanceSheet!F21 -> -1.236
A12: Net Cash from Operations | B12: 92.1 | C12: 83.6 | D12: 92.9 | E12: 88.4 | F12: 95 | G12: 105
A14: INVESTING ACTIVITIES
A15: Capital expenditure | B15: =-'P&L'!B10*Assumptions!B24 -> -20.3532 | C15: =-'P&L'!C10*Assumptions!C24 -> -22.9548 | D15: =-'P&L'!D10*Assumptions!D24 -> -19.1202 | E15: =-'P&L'!E10*Assumptions!E24 -> -23.8946 | F15: =-'P&L'!F10*Assumptions!F24 -> -25.010409 | G15: =-'P&L'!G10*Assumptions!G24 -> -24.814286
A16: Net Cash from Investing | B16: =B15 -> -20.3532 | C16: =C15 -> -22.9548 | D16: =D15 -> -19.1202 | E16: =E15 -> -23.8946 | F16: =F15 -> -25.010409 | G16: =G15 -> -24.814286
A18: FINANCING ACTIVITIES
A19: Proceeds from / (repayment of) borrowings | B19: -0.7 | C19: -0.5 | D19: -1.5 | E19: 33 | F19: -5 | G19: -5
A20: Interest paid | B20: -0.1 | C20: -0.1 | D20: 0 | E20: -3 | F20: ='P&L'!F35 -> -6.5 | G20: ='P&L'!G35 -> -6
A21: Dividends paid | B21: -13.3 | C21: -15.2 | D21: -17.3 | E21: -18.9 | F21: =E21*1.05 -> -19.845 | G21: =F21*1.05 -> -20.83725
A22: Net Cash from Financing | B22: =SUM(B19:B21) -> -14.1 | C22: =SUM(C19:C21) -> -15.8 | D22: =SUM(D19:D21) -> -18.8 | E22: =SUM(E19:E21) -> 11.1 | F22: =SUM(F19:F21) -> -31.345 | G22: =SUM(G19:G21) -> -31.83725
A24: CASH MOVEMENT
A25: Opening cash balance | B25: 52.8 | C25: =B27 -> 110.4468 | D25: =C27 -> 155.292 | E25: =D27 -> 210.2718 | F25: 23.7 | G25: =F27 -> 62.344591
A26: Net change in cash | B26: =B12+B16+B22 -> 57.6468 | C26: =C12+C16+C22 -> 44.8452 | D26: =D12+D16+D22 -> 54.9798 | E26: =E12+E16+E22 -> 75.6054 | F26: =F12+F16+F22 -> 38.644591 | G26: =G12+G16+G22 -> 48.348464
A27: Closing cash balance | B27: =B25+B26 -> 110.4468 | C27: =C25+C26 -> 155.292 | D27: =D25+D26 -> 210.2718 | E27: =E25+E26 -> 285.8772 | F27: =F25+F26 -> 62.344591 | G27: =G25+G26 -> 110.69306
A34: Net change in cash (used by BS) | B34: =B26 -> 57.6468 | C34: =C26 -> 44.8452 | D34: =D26 -> 54.9798 | E34: =E26 -> 75.6054 | F34: =F26 -> 38.644591 | G34: =G26 -> 48.348464

Sheet KPI Dashboard
A1: GAMMA COMMUNICATIONS PLC | KPI & RATIO DASHBOARD
A2: Summary metrics for exec reporting | Formulas pull from P&L, BS, CF sheets
A4: KPI | B4: FY2022A | C4: FY2023A | D4: FY2024A | E4: FY2025A | F4: FY2026E | G4: FY2027E
A5: GROWTH
A6: Revenue (£m) | B6: ='P&L'!B10 -> 484.6 | C6: ='P&L'!C10 -> 521.7 | D6: ='P&L'!D10 -> 579.4 | E6: ='P&L'!E10 -> 645.8 | F6: ='P&L'!F10 -> 675.957 | G6: ='P&L'!G10 -> 708.97959
A7: Revenue growth YoY
A8: EBITDA (£m) | B8: ='P&L'!B24 -> 105.1 | C8: ='P&L'!C24 -> 114.3 | D8: ='P&L'!D24 -> 125.5 | E8: ='P&L'!E24 -> 141.7 | F8: ='P&L'!F24 -> 155.80456 | G8: ='P&L'!G24 -> 167.42412
A9: EBITDA margin | B9: ='P&L'!B25 -> 0.2168799 | C9: ='P&L'!C25 -> 0.21909143 | D9: ='P&L'!D25 -> 0.21660338 | E9: ='P&L'!E25 -> 0.21941778 | F9: ='P&L'!F25 -> 0.23049479 | G9: ='P&L'!G25 -> 0.23614801
A10: Net Income (£m) | B10: ='P&L'!B36 -> 64.9 | C10: ='P&L'!C36 -> 71.5 | D10: ='P&L'!D36 -> 97 | E10: ='P&L'!E36 -> 87.9 | F10: ='P&L'!F36 -> 96.728005 | G10: ='P&L'!G36 -> 106.70575
A11: Net margin | B11: ='P&L'!B37 -> -15.4 | C11: ='P&L'!C37 -> -17.8 | D11: ='P&L'!D37 -> -25.8 | E11: ='P&L'!E37 -> -22.7 | F11: ='P&L'!F37 -> -24.182001 | G11: ='P&L'!G37 -> -26.676437
A12: PROFITABILITY
A13: Gross margin | B13: ='P&L'!B15 -> 0.51114321 | C13: ='P&L'!C15 -> 0.51217175 | D13: ='P&L'!D15 -> 0.51829479 | E13: ='P&L'!E15 -> 0.53917622 | F13: ='P&L'!F15 -> 0.545 | G13: ='P&L'!G15 -> 0.545
A14: EBIT margin | B14: ='P&L'!B30 -> 65.4 | C14: ='P&L'!C30 -> 67 | D14: ='P&L'!D30 -> 91.7 | E14: ='P&L'!E30 -> 91.1 | F14: ='P&L'!F30 -> 101.728 | G14: ='P&L'!G30 -> 110.70575
A15: BALANCE SHEET
A16: Total assets (£m) | B16: =BalanceSheet!B17 -> 372.3 | C16: =BalanceSheet!C17 -> 442.1 | D16: =BalanceSheet!D17 -> 502 | E16: =BalanceSheet!E17 -> 588.2 | F16: =BalanceSheet!F17 -> 559.94575 | G16: =BalanceSheet!G17 -> 553.75496
A17: Net debt (£m)
A18: CASH FLOW
A19: Operating CF (£m) | B19: =CashFlow!B12 -> 92.1 | C19: =CashFlow!C12 -> 83.6 | D19: =CashFlow!D12 -> 92.9 | E19: =CashFlow!E12 -> 88.4 | F19: =CashFlow!F12 -> 95 | G19: =CashFlow!G12 -> 105
A20: Capex (£m) | B20: =CashFlow!B15 -> -20.3532 | C20: =CashFlow!C15 -> -22.9548 | D20: =CashFlow!D15 -> -19.1202 | E20: =CashFlow!E15 -> -23.8946 | F20: =CashFlow!F15 -> -25.010409 | G20: =CashFlow!G15 -> -24.814286
A21: Free Cash Flow
A22: SUBSCRIBERS
A23: Mobile subs (000s) | B23: =Assumptions!B6 -> 309.4 | C23: =Assumptions!C6 -> 332.2 | D23: =Assumptions!D6 -> 368.9 | E23: =Assumptions!E6 -> 374.6 | F23: =Assumptions!F6 -> 382.092 | G23: =Assumptions!G6 -> 389.73384
A24: BB subs (000s) | B24: =Assumptions!B10 -> 43 | C24: =Assumptions!C10 -> 47.2 | D24: =Assumptions!D10 -> 54.3 | E24: =Assumptions!E10 -> 110.2 | F24: =Assumptions!F10 -> 126.73 | G24: =Assumptions!G10 -> 145.7395
